Workbook
Name NativeTimeline_Date: #N/A
Name NativeTimeline_Date1: #N/A
Name NativeTimeline_Date2: #N/A
Name NativeTimeline_Date5: #N/A
Name Slicer_Date: #N/A
Name Slicer_Date1: #N/A
Name Slicer_Date2: #N/A
Name Slicer_Date3: #N/A
Name Slicer_Date31: #N/A
Name Slicer_Date311: #N/A
Name Slicer_Date3111: #N/A
Name Slicer_Date312: #N/A
Name Slicer_Date4: #N/A
Name Slicer_Date41: #N/A
Name Slicer_Date411: #N/A
Name Slicer_Date4111: #N/A
Name Slicer_Date42: #N/A
Name Slicer_Date5: #N/A
Name Slicer_Date6: #N/A
Name Slicer_Plant: #N/A
Name Slicer_Plant1: #N/A
Name Slicer_Plant2: #N/A
Name Slicer_WorkCell: #N/A
Name Slicer_WorkCell_Group: #N/A
Name Slicer_WorkCell_Group1: #N/A
Name Slicer_WorkCell1: #N/A
Name Slicer_WorkCell11: #N/A
Name Slicer_WorkCell111: #N/A
Name Slicer_WorkCell112: #N/A
Name Slicer_WorkCell1121: #N/A
Name Slicer_WorkCell11211: #N/A
Name Slicer_WorkCell112111: #N/A
Name Slicer_WorkCell11212: #N/A
Name Slicer_WorkCell113: #N/A
Name Slicer_WorkCell1131: #N/A
Name Slicer_WorkCell11311: #N/A
Name Slicer_WorkCell113111: #N/A
Name Slicer_WorkCell1132: #N/A
Name Slicer_WorkCell2: #N/A
Name Slicer_WorkCell3: #N/A
Name Slicer_WorkCell4: #N/A

Sheet Untagged Plant
A1: Plant | B1: (All)
A3: Row Labels | B3: Untagged Target | C3: Untagged vs Loss | D3: Untagged Hours
A4: 1Pc Autocoiner 1 (789) | B4: 0.05 | C4: 0.008624002 | D4: 2.02
A5: 1Pc Autocoiner 2 (844) | B5: 0.05 | C5: 0.013278856 | D5: 2.47
A6: 1pc Autocoiner 9 (34753) | B6: 0.05 | C6: 0.044657904 | D6: 13.25
A7: 1PCAC10 | B7: 0.05 | C7: 0.012009696 | D7: 2.18
A8: 2Pc Autocoiner 3 (796) | B8: 0.05 | C8: 0.35497037 | D8: 90.45
A9: 2Pc Autocoiner 4 (843) | B9: 0.05 | C9: 0.31779506 | D9: 69.47
A10: 2Pc Autocoiner 5 (858) | B10: 0.05 | C10: 0.27406481 | D10: 46.01
A11: 2Pc Autocoiner 7 (996) | B11: 0.05 | C11: 0.2928508 | D11: 65.95
A12: 2PCAC06 | B12: 0.05 | C12: 0.025356734 | D12: 5.1
A13: AC08 | B13: 0.05 | C13: 0.013200061 | D13: 1.73
A14: AC09 | B14: 0.05 | C14: 0.036812009 | D14: 2.06
A15: AC10 | B15: 0.05 | C15: 0.026811267 | D15: 1.78
... A64: Grand Total | B64: 0.05 | C64: 0.20419883 | D64: 3140.19

Sheet Plant Output
A33: Row Labels | B33: Target Output | C33: Output
A34: BA | B34: 2.688798e+08 | C34: 360929877
A35: 2024 | B35: 1.3140034e+08 | C35: 130732073
A36: Qtr1 | B36: 32902270 | C36: 32533734
A37: Jan | B37: 10300735 | C37: 10299274
A38: 45292 | B38: 10300735 | C38: 10299274
A39: Autocoiner #3 | B39: 402702.54 | C39: 389000
A40: Autocoiner #4 | B40: 402702.54 | C40: 381600
A41: Autocoiner #5 | B41: 402702.54 | C41: 381180
A42: Autocoiner #6 | B42: 402702.54 | C42: 348200
A43: Autocoiner #7 | B43: 431775 | C43: 450180
A44: Autocoiner #8 | B44: 431775 | C44: 448440
A45: BIM 12 | B45: 206152.88 | C45: 599715
A46: BIM03 | B46: 456993.97 | C46: 421180
A47: BIM08 | B47: 765711.78 | C47: 585285
A48: HF11 | B48: 849563.58 | C48: 759000
A49: HU2 | B49: 794534.49 | C49: 809470
A50: Kiefel 10 | B50: 660633.59 | C50: 643380
... A56: Feb | B56: 10350658 | C56: 10477611
A57: 45323 | B57: 10350658 | C57: 10477611
A58: Autocoiner #3 | B58: 381507.67 | C58: 368700
A59: Autocoiner #4 | B59: 381507.67 | C59: 380940
A60: Autocoiner #5 | B60: 381507.67 | C60: 373860
A61: Autocoiner #6 | B61: 381507.67 | C61: 354900
A62: Autocoiner #7 | B62: 409050 | C62: 477000
A63: Autocoiner #8 | B63: 409050 | C63: 450750
A64: BIM 12 | B64: 195302.73 | C64: 504974
A65: BIM03 | B65: 432941.66 | C65: 428730
A66: BIM08 | B66: 725411.16 | C66: 574616
A67: HF11 | B67: 804849.71 | C67: 759360
A68: HU2 | B68: 752716.88 | C68: 701340
A69: Kiefel 10 | B69: 625863.4 | C69: 663501
... A76: Mar | B76: 12250877 | C76: 11756849
A77: 45352 | B77: 12250877 | C77: 11756849
A78: Autocoiner #3 | B78: 409767.5 | C78: 367900
A79: Autocoiner #4 | B79: 409767.5 | C79: 435800
A80: Autocoiner #5 | B80: 409767.5 | C80: 387540
A81: Autocoiner #6 | B81: 409767.5 | C81: 366400
A82: Autocoiner #7 | B82: 439350 | C82: 482400
A83: Autocoiner #8 | B83: 439350 | C83: 466630
...

Sheet Output Tables
A1: Date Range | E1: 46023 | F1: 46082
C3: WorkCell | D3: Machine | E3: YTD Target Output | F3: YTD Actual | G3: Surplus / Deficit | H3: Stated Capacity | I3: Surplus / Deficit Capacity
A4: STUARTS DRAFT | B4: POUCH | C4: Kiefel6 (791) | D4: =_xlfn.XLOOKUP(C4,#REF!,#REF!,0) -> #REF! | E4: {=SUMPRODUCT((#REF! = 'Output Tables'!C4) * (#REF! >= 'Output Tables'!$E$1) * (#REF! <= 'Output Tables'!$F$1) * #REF!)} -> #REF! | F4: {=SUMPRODUCT((#REF! = 'Output Tables'!D4) * (#REF! >= 'Output Tables'!$E$1) * (#REF! <= 'Output Tables'!$F$1) *#REF!)} -> #REF! | G4: =F4-E4 -> #REF! | H4: {=SUMPRODUCT((#REF! = 'Output Tables'!$D4) * (#REF! >= 'Output Tables'!$E$1) * (#REF! <= 'Output Tables'!$F$1) *#REF!)} -> #REF! | I4: =F4-H4 -> #REF!
C5: Kiefel8 (793) | D5: =_xlfn.XLOOKUP(C5,#REF!,#REF!,0) -> #REF! | E5: {=SUMPRODUCT((#REF! = 'Output Tables'!C5) * (#REF! >= 'Output Tables'!$E$1) * (#REF! <= 'Output Tables'!$F$1) * #REF!)} -> #REF! | F5: {=SUMPRODUCT((#REF! = 'Output Tables'!D5) * (#REF! >= 'Output Tables'!$E$1) * (#REF! <= 'Output Tables'!$F$1) *#REF!)} -> #REF! | G5: =F5-E5 -> #REF! | H5: {=SUMPRODUCT((#REF! = 'Output Tables'!$D5) * (#REF! >= 'Output Tables'!$E$1) * (#REF! <= 'Output Tables'!$F$1) *#REF!)} -> #REF! | I5: =F5-H5 -> #REF!
C6: Keifel11 (978) | D6: =_xlfn.XLOOKUP(C6,#REF!,#REF!,0) -> #REF! | E6: {=SUMPRODUCT((#REF! = 'Output Tables'!C6) * (#REF! >= 'Output Tables'!$E$1) * (#REF! <= 'Output Tables'!$F$1) * #REF!)} -> #REF! | F6: {=SUMPRODUCT((#REF! = 'Output Tables'!D6) * (#REF! >= 'Output Tables'!$E$1) * (#REF! <= 'Output Tables'!$F$1) *#REF!)} -> #REF! | G6: =F6-E6 -> #REF! | H6: {=SUMPRODUCT((#REF! = 'Output Tables'!$D6) * (#REF! >= 'Output Tables'!$E$1) * (#REF! <= 'Output Tables'!$F$1) *#REF!)} -> #REF! | I6: =F6-H6 -> #REF!
C7: Keifel12 (979) | D7: =_xlfn.XLOOKUP(C7,#REF!,#REF!,0) -> #REF! | E7: {=SUMPRODUCT((#REF! = 'Output Tables'!C7) * (#REF! >= 'Output Tables'!$E$1) * (#REF! <= 'Output Tables'!$F$1) * #REF!)} -> #REF! | F7: {=SUMPRODUCT((#REF! = 'Output Tables'!D7) * (#REF! >= 'Output Tables'!$E$1) * (#REF! <= 'Output Tables'!$F$1) *#REF!)} -> #REF! | G7: =F7-E7 -> #REF! | H7: {=SUMPRODUCT((#REF! = 'Output Tables'!$D7) * (#REF! >= 'Output Tables'!$E$1) * (#REF! <= 'Output Tables'!$F$1) *#REF!)} -> #REF! | I7: =F7-H7 -> #REF!
C8: Kiefel5 (790) | D8: =_xlfn.XLOOKUP(C8,#REF!,#REF!,0) -> #REF! | E8: {=SUMPRODUCT((#REF! = 'Output Tables'!C8) * (#REF! >= 'Output Tables'!$E$1) * (#REF! <= 'Output Tables'!$F$1) * #REF!)} -> #REF! | F8: {=SUMPRODUCT((#REF! = 'Output Tables'!D8) * (#REF! >= 'Output Tables'!$E$1) * (#REF! <= 'Output Tables'!$F$1) *#REF!)} -> #REF! | G8: =F8-E8 -> #REF! | H8: {=SUMPRODUCT((#REF! = 'Output Tables'!$D8) * (#REF! >= 'Output Tables'!$E$1) * (#REF! <= 'Output Tables'!$F$1) *#REF!)} -> #REF! | I8: =F8-H8 -> #REF!
C9: HU1 (849) | D9: =_xlfn.XLOOKUP(C9,#REF!,#REF!,0) -> #REF! | E9: {=SUMPRODUCT((#REF! = 'Output Tables'!C9) * (#REF! >= 'Output Tables'!$E$1) * (#REF! <= 'Output Tables'!$F$1) * #REF!)} -> #REF! | F9: {=SUMPRODUCT((#REF! = 'Output Tables'!D9) * (#REF! >= 'Output Tables'!$E$1) * (#REF! <= 'Output Tables'!$F$1) *#REF!)} -> #REF! | G9: =F9-E9 -> #REF! | H9: {=SUMPRODUCT((#REF! = 'Output Tables'!$D9) * (#REF! >= 'Output Tables'!$E$1) * (#REF! <= 'Output Tables'!$F$1) *#REF!)} -> #REF! | I9: =F9-H9 -> #REF!
C10: 1Pc Autocoiner 1 (789) | D10: =_xlfn.XLOOKUP(C10,#REF!,#REF!,0) -> #REF! | E10: {=SUMPRODUCT((#REF! = 'Output Tables'!C10) * (#REF! >= 'Output Tables'!$E$1) * (#REF! <= 'Output Tables'!$F$1) * #REF!)} -> #REF! | F10: {=SUMPRODUCT((#REF! = 'Output Tables'!D10) * (#REF! >= 'Output Tables'!$E$1) * (#REF! <= 'Output Tables'!$F$1) *#REF!)} -> #REF! | G10: =F10-E10 -> #REF! | H10: {=SUMPRODUCT((#REF! = 'Output Tables'!$D10) * (#REF! >= 'Output Tables'!$E$1) * (#REF! <= 'Output Tables'!$F$1) *#REF!)} -> #REF! | I10: =F10-H10 -> #REF!
C11: 1Pc Autocoiner 2 (844) | D11: =_xlfn.XLOOKUP(C11,#REF!,#REF!,0) -> #REF! | E11: {=SUMPRODUCT((#REF! = 'Output Tables'!C11) * (#REF! >= 'Output Tables'!$E$1) * (#REF! <= 'Output Tables'!$F$1) * #REF!)} -> #REF! | F11: {=SUMPRODUCT((#REF! = 'Output Tables'!D11) * (#REF! >= 'Output Tables'!$E$1) * (#REF! <= 'Output Tables'!$F$1) *#REF!)} -> #REF! | G11: =F11-E11 -> #REF! | H11: {=SUMPRODUCT((#REF! = 'Output Tables'!$D11) * (#REF! >= 'Output Tables'!$E$1) * (#REF! <= 'Output Tables'!$F$1) *#REF!)} -> #REF! | I11: =F11-H11 -> #REF!
C12: 1pc Autocoiner 9 (34753) | D12: =_xlfn.XLOOKUP(C12,#REF!,#REF!,0) -> #REF! | E12: {=SUMPRODUCT((#REF! = 'Output Tables'!C12) * (#REF! >= 'Output Tables'!$E$1) * (#REF! <= 'Output Tables'!$F$1) * #REF!)} -> #REF! | F12: {=SUMPRODUCT((#REF! = 'Output Tables'!D12) * (#REF! >= 'Output Tables'!$E$1) * (#REF! <= 'Output Tables'!$F$1) *#REF!)} -> #REF! | G12: =F12-E12 -> #REF! | H12: {=SUMPRODUCT((#REF! = 'Output Tables'!$D12) * (#REF! >= 'Output Tables'!$E$1) * (#REF! <= 'Output Tables'!$F$1) *#REF!)} -> #REF! | I12: =F12-H12 -> #REF!
B13: BARRIER | C13: BIM 1 (815) | D13: =_xlfn.XLOOKUP(C13,#REF!,#REF!,0) -> #REF! | E13: {=SUMPRODUCT((#REF! = 'Output Tables'!C13) * (#REF! >= 'Output Tables'!$E$1) * (#REF! <= 'Output Tables'!$F$1) * #REF!)} -> #REF! | F13: {=SUMPRODUCT((#REF! = 'Output Tables'!D13) * (#REF! >= 'Output Tables'!$E$1) * (#REF! <= 'Output Tables'!$F$1) *#REF!)} -> #REF! | G13: =F13-E13 -> #REF! | H13: {=SUMPRODUCT((#REF! = 'Output Tables'!$D13) * (#REF! >= 'Output Tables'!$E$1) * (#REF! <= 'Output Tables'!$F$1) *#REF!)} -> #REF! | I13: =F13-H13 -> #REF!
C14: BIM 2 (820) | D14: =_xlfn.XLOOKUP(C14,#REF!,#REF!,0) -> #REF! | E14: {=SUMPRODUCT((#REF! = 'Output Tables'!C14) * (#REF! >= 'Output Tables'!$E$1) * (#REF! <= 'Output Tables'!$F$1) * #REF!)} -> #REF! | F14: {=SUMPRODUCT((#REF! = 'Output Tables'!D14) * (#REF! >= 'Output Tables'!$E$1) * (#REF! <= 'Output Tables'!$F$1) *#REF!)} -> #REF! | G14: =F14-E14 -> #REF! | H14: {=SUMPRODUCT((#REF! = 'Output Tables'!$D14) * (#REF! >= 'Output Tables'!$E$1) * (#REF! <= 'Output Tables'!$F$1) *#REF!)} -> #REF! | I14: =F14-H14 -> #REF!
C15: BIM 4 (828) | D15: =_xlfn.XLOOKUP(C15,#REF!,#REF!,0) -> #REF! | E15: {=SUMPRODUCT((#REF! = 'Output Tables'!C15) * (#REF! >= 'Output Tables'!$E$1) * (#REF! <= 'Output Tables'!$F$1) * #REF!)} -> #REF! | F15: {=SUMPRODUCT((#REF! = 'Output Tables'!D15) * (#REF! >= 'Output Tables'!$E$1) * (#REF! <= 'Output Tables'!$F$1) *#REF!)} -> #REF! | G15: =F15-E15 -> #REF! | H15: {=SUMPRODUCT((#REF! = 'Output Tables'!$D15) * (#REF! >= 'Output Tables'!$E$1) * (#REF! <= 'Output Tables'!$F$1) *#REF!)} -> #REF! | I15: =F15-H15 -> #REF!
C16: BIM 6 (788) | D16: =_xlfn.XLOOKUP(C16,#REF!,#REF!,0) -> #REF! | E16: {=SUMPRODUCT((#REF! = 'Output Tables'!C16) * (#REF! >= 'Output Tables'!$E$1) * (#REF! <= 'Output Tables'!$F$1) * #REF!)} -> #REF! | F16: {=SUMPRODUCT((#REF! = 'Output Tables'!D16) * (#REF! >= 'Output Tables'!$E$1) * (#REF! <= 'Output Tables'!$F$1) *#REF!)} -> #REF! | G16: =F16-E16 -> #REF! | H16: {=SUMPRODUCT((#REF! = 'Output Tables'!$D16) * (#REF! >= 'Output Tables'!$E$1) * (#REF! <= 'Output Tables'!$F$1) *#REF!)} -> #REF! | I16: =F16-H16 -> #REF!
C17: BIM 7 (798) | D17: =_xlfn.XLOOKUP(C17,#REF!,#REF!,0) -> #REF! | E17: {=SUMPRODUCT((#REF! = 'Output Tables'!C17) * (#REF! >= 'Output Tables'!$E$1) * (#REF! <= 'Output Tables'!$F$1) * #REF!)} -> #REF! | F17: {=SUMPRODUCT((#REF! = 'Output Tables'!D17) * (#REF! >= 'Output Tables'!$E$1) * (#REF! <= 'Output Tables'!$F$1) *#REF!)} -> #REF! | G17: =F17-E17 -> #REF! | H17: {=SUMPRODUCT((#REF! = 'Output Tables'!$D17) * (#REF! >= 'Output Tables'!$E$1) * (#REF! <= 'Output Tables'!$F$1) *#REF!)} -> #REF! | I17: =F17-H17 -> #REF!
C18: BIM 9 (977) | D18: =_xlfn.XLOOKUP(C18,#REF!,#REF!,0) -> #REF! | E18: {=SUMPRODUCT((#REF! = 'Output Tables'!C18) * (#REF! >= 'Output Tables'!$E$1) * (#REF! <= 'Output Tables'!$F$1) * #REF!)} -> #REF! | F18: {=SUMPRODUCT((#REF! = 'Output Tables'!D18) * (#REF! >= 'Output Tables'!$E$1) * (#REF! <= 'Output Tables'!$F$1) *#REF!)} -> #REF! | G18: =F18-E18 -> #REF! | H18: {=SUMPRODUCT((#REF! = 'Output Tables'!$D18) * (#REF! >= 'Output Tables'!$E$1) * (#REF! <= 'Output Tables'!$F$1) *#REF!)} -> #REF! | I18: =F18-H18 -> #REF!
C19: BIM 10 (997) | D19: =_xlfn.XLOOKUP(C19,#REF!,#REF!,0) -> #REF! | E19: {=SUMPRODUCT((#REF! = 'Output Tables'!C19) * (#REF! >= 'Output Tables'!$E$1) * (#REF! <= 'Output Tables'!$F$1) * #REF!)} -> #REF! | F19: {=SUMPRODUCT((#REF! = 'Output Tables'!D19) * (#REF! >= 'Output Tables'!$E$1) * (#REF! <= 'Output Tables'!$F$1) *#REF!)} -> #REF! | G19: =F19-E19 -> #REF! | H19: {=SUMPRODUCT((#REF! = 'Output Tables'!$D19) * (#REF! >= 'Output Tables'!$E$1) * (#REF! <= 'Output Tables'!$F$1) *#REF!)} -> #REF! | I19: =F19-H19 -> #REF!
C20: BIM 11 (991) | D20: =_xlfn.XLOOKUP(C20,#REF!,#REF!,0) -> #REF! | E20: {=SUMPRODUCT((#REF! = 'Output Tables'!C20) * (#REF! >= 'Output Tables'!$E$1) * (#REF! <= 'Output Tables'!$F$1) * #REF!)} -> #REF! | F20: {=SUMPRODUCT((#REF! = 'Output Tables'!D20) * (#REF! >= 'Output Tables'!$E$1) * (#REF! <= 'Output Tables'!$F$1) *#REF!)} -> #REF! | G20: =F20-E20 -> #REF! | H20: {=SUMPRODUCT((#REF! = 'Output Tables'!$D20) * (#REF! >= 'Output Tables'!$E$1) * (#REF! <= 'Output Tables'!$F$1) *#REF!)} -> #REF! | I20: =F20-H20 -> #REF!
C21: BIM 17 | D21: =_xlfn.XLOOKUP(C21,#REF!,#REF!,0) -> #REF! | E21: {=SUMPRODUCT((#REF! = 'Output Tables'!C21) * (#REF! >= 'Output Tables'!$E$1) * (#REF! <= 'Output Tables'!$F$1) * #REF!)} -> #REF! | F21: {=SUMPRODUCT((#REF! = 'Output Tables'!D21) * (#REF! >= 'Output Tables'!$E$1) * (#REF! <= 'Output Tables'!$F$1) *#REF!)} -> #REF! | G21: =F21-E21 -> #REF! | H21: {=SUMPRODUCT((#REF! = 'Output Tables'!$D21) * (#REF! >= 'Output Tables'!$E$1) * (#REF! <= 'Output Tables'!$F$1) *#REF!)} -> #REF! | I21: =F21-H21 -> #REF!
C22: 2Pc Autocoiner 3 (796) | D22: =_xlfn.XLOOKUP(C22,#REF!,#REF!,0) -> #REF! | E22: {=SUMPRODUCT((#REF! = 'Output Tables'!C22) * (#REF! >= 'Output Tables'!$E$1) * (#REF! <= 'Output Tables'!$F$1) * #REF!)} -> #REF! | F22: {=SUMPRODUCT((#REF! = 'Output Tables'!D22) * (#REF! >= 'Output Tables'!$E$1) * (#REF! <= 'Output Tables'!$F$1) *#REF!)} -> #REF! | G22: =F22-E22 -> #REF! | H22: {=SUMPRODUCT((#REF! = 'Output Tables'!$D22) * (#REF! >= 'Output Tables'!$E$1) * (#REF! <= 'Output Tables'!$F$1) *#REF!)} -> #REF! | I22: =F22-H22 -> #REF!
C23: 2Pc Autocoiner 4 (843) | D23: =_xlfn.XLOOKUP(C23,#REF!,#REF!,0) -> #REF! | E23: {=SUMPRODUCT((#REF! = 'Output Tables'!C23) * (#REF! >= 'Output Tables'!$E$1) * (#REF! <= 'Output Tables'!$F$1) * #REF!)} -> #REF! | F23: {=SUMPRODUCT((#REF! = 'Output Tables'!D23) * (#REF! >= 'Output Tables'!$E$1) * (#REF! <= 'Output Tables'!$F$1) *#REF!)} -> #REF! | G23: =F23-E23 -> #REF! | H23: {=SUMPRODUCT((#REF! = 'Output Tables'!$D23) * (#REF! >= 'Output Tables'!$E$1) * (#REF! <= 'Output Tables'!$F$1) *#REF!)} -> #REF! | I23: =F23-H23 -> #REF!
C24: 2Pc Autocoiner 5 (858) | D24: =_xlfn.XLOOKUP(C24,#REF!,#REF!,0) -> #REF! | E24: {=SUMPRODUCT((#REF! = 'Output Tables'!C24) * (#REF! >= 'Output Tables'!$E$1) * (#REF! <= 'Output Tables'!$F$1) * #REF!)} -> #REF! | F24: {=SUMPRODUCT((#REF! = 'Output Tables'!D24) * (#REF! >= 'Output Tables'!$E$1) * (#REF! <= 'Output Tables'!$F$1) *#REF!)} -> #REF! | G24: =F24-E24 -> #REF! | H24: {=SUMPRODUCT((#REF! = 'Output Tables'!$D24) * (#REF! >= 'Output Tables'!$E$1) * (#REF! <= 'Output Tables'!$F$1) *#REF!)} -> #REF! | I24: =F24-H24 -> #REF!
C25: 2Pc Autocoiner 7 (996) | D25: =_xlfn.XLOOKUP(C25,#REF!,#REF!,0) -> #REF! | E25: {=SUMPRODUCT((#REF! = 'Output Tables'!C25) * (#REF! >= 'Output Tables'!$E$1) * (#REF! <= 'Output Tables'!$F$1) * #REF!)} -> #REF! | F25: {=SUMPRODUCT((#REF! = 'Output Tables'!D25) * (#REF! >= 'Output Tables'!$E$1) * (#REF! <= 'Output Tables'!$F$1) *#REF!)} -> #REF! | G25: =F25-E25 -> #REF! | H25: {=SUMPRODUCT((#REF! = 'Output Tables'!$D25) * (#REF! >= 'Output Tables'!$E$1) * (#REF! <= 'Output Tables'!$F$1) *#REF!)} -> #REF! | I25: =F25-H25 -> #REF!
C26: Extruder 4 (994) | D26: =_xlfn.XLOOKUP(C26,#REF!,#REF!,0) -> #REF! | E26: {=SUMPRODUCT((#REF! = 'Output Tables'!C26) * (#REF! >= 'Output Tables'!$E$1) * (#REF! <= 'Output Tables'!$F$1) * #REF!)} -> #REF! | F26: {=SUMPRODUCT((#REF! = 'Output Tables'!D26) * (#REF! >= 'Output Tables'!$E$1) * (#REF! <= 'Output Tables'!$F$1) *#REF!)} -> #REF! | G26: =F26-E26 -> #REF! | H26: {=SUMPRODUCT((#REF! = 'Output Tables'!$D26) * (#REF! >= 'Output Tables'!$E$1) * (#REF! <= 'Output Tables'!$F$1) *#REF!)} -> #REF! | I26: =F26-H26 -> #REF!
D27: TOTAL | E27: =SUM(E4:E26) -> #REF! | F27: =SUM(F4:F26) -> #REF! | G27: =SUM(G4:G26) -> #REF! | H27: =SUM(H4:H26) -> #REF! | I27: =F27-H27 -> #REF!
D30: Machine | E30: YTD Target Output | F30: YTD Actual | G30: Surplus / Deficit | H30: Stated Capacity | I30: Surplus / Deficit Capacity
A31: BALLINA | B31: POUCH | C31: Kiefel 3 | D31: =_xlfn.XLOOKUP(C31,#REF!,#REF!,0) -> #REF! | E31: {=SUMPRODUCT((#REF! = 'Output Tables'!C31) * (#REF! >= 'Output Tables'!$E$1) * (#REF! <= 'Output Tables'!$F$1) * #REF!)} -> #REF! | F31: {=SUMPRODUCT((#REF! = 'Output Tables'!D31) * (#REF! >= 'Output Tables'!$E$1) * (#REF! <= 'Output Tables'!$F$1) *#REF!)} -> #REF! | G31: =F31-E31 -> #REF! | H31: {=SUMPRODUCT((#REF! = 'Output Tables'!$D31) * (#REF! >= 'Output Tables'!$E$1) * (#REF! <= 'Output Tables'!$F$1) *#REF!)} -> #REF! | I31: =F31-H31 -> #REF!
C32: Kiefel 9 | D32: =_xlfn.XLOOKUP(C32,#REF!,#REF!,0) -> #REF! | E32: {=SUMPRODUCT((#REF! = 'Output Tables'!C32) * (#REF! >= 'Output Tables'!$E$1) * (#REF! <= 'Output Tables'!$F$1) * #REF!)} -> #REF! | F32: {=SUMPRODUCT((#REF! = 'Output Tables'!D32) * (#REF! >= 'Output Tables'!$E$1) * (#REF! <= 'Output Tables'!$F$1) *#REF!)} -> #REF! | G32: =F32-E32 -> #REF! | H32: {=SUMPRODUCT((#REF! = 'Output Tables'!$D32) * (#REF! >= 'Output Tables'!$E$1) * (#REF! <= 'Output Tables'!$F$1) *#REF!)} -> #REF! | I32: =F32-H32 -> #REF!
C33: Kiefel 14 | D33: =_xlfn.XLOOKUP(C33,#REF!,#REF!,0) -> #REF! | E33: {=SUMPRODUCT((#REF! = 'Output Tables'!C33) * (#REF! >= 'Output Tables'!$E$1) * (#REF! <= 'Output Tables'!$F$1) * #REF!)} -> #REF! | F33: {=SUMPRODUCT((#REF! = 'Output Tables'!D33) * (#REF! >= 'Output Tables'!$E$1) * (#REF! <= 'Output Tables'!$F$1) *#REF!)} -> #REF! | G33: =F33-E33 -> #REF! | H33: {=SUMPRODUCT((#REF! = 'Output Tables'!$D33) * (#REF! >= 'Output Tables'!$E$1) * (#REF! <= 'Output Tables'!$F$1) *#REF!)} -> #REF! | I33: =F33-H33 -> #REF!
C34: Kiefel 10 | D34: =_xlfn.XLOOKUP(C34,#REF!,#REF!,0) -> #REF! | E34: {=SUMPRODUCT((#REF! = 'Output Tables'!C34) * (#REF! >= 'Output Tables'!$E$1) * (#REF! <= 'Output Tables'!$F$1) * #REF!)} -> #REF! | F34: {=SUMPRODUCT((#REF! = 'Output Tables'!D34) * (#REF! >= 'Output Tables'!$E$1) * (#REF! <= 'Output Tables'!$F$1) *#REF!)} -> #REF! | G34: =F34-E34 -> #REF! | H34: {=SUMPRODUCT((#REF! = 'Output Tables'!$D34) * (#REF! >= 'Output Tables'!$E$1) * (#REF! <= 'Output Tables'!$F$1) *#REF!)} -> #REF! | I34: =F34-H34 -> #REF!
C35: Kiefel 13 | D35: =_xlfn.XLOOKUP(C35,#REF!,#REF!,0) -> #REF! | E35: {=SUMPRODUCT((#REF! = 'Output Tables'!C35) * (#REF! >= 'Output Tables'!$E$1) * (#REF! <= 'Output Tables'!$F$1) * #REF!)} -> #REF! | F35: {=SUMPRODUCT((#REF! = 'Output Tables'!D35) * (#REF! >= 'Output Tables'!$E$1) * (#REF! <= 'Output Tables'!$F$1) *#REF!)} -> #REF! | G35: =F35-E35 -> #REF! | H35: {=SUMPRODUCT((#REF! = 'Output Tables'!$D35) * (#REF! >= 'Output Tables'!$E$1) * (#REF! <= 'Output Tables'!$F$1) *#REF!)} -> #REF! | I35: =F35-H35 -> #REF!
C36: P16 | D36: =_xlfn.XLOOKUP(C36,#REF!,#REF!,0) -> #REF! | E36: {=SUMPRODUCT((#REF! = 'Output Tables'!C36) * (#REF! >= 'Output Tables'!$E$1) * (#REF! <= 'Output Tables'!$F$1) * #REF!)} -> #REF! | F36: {=SUMPRODUCT((#REF! = 'Output Tables'!D36) * (#REF! >= 'Output Tables'!$E$1) * (#REF! <= 'Output Tables'!$F$1) *#REF!)} -> #REF! | G36: =F36-E36 -> #REF! | H36: {=SUMPRODUCT((#REF! = 'Output Tables'!$D36) * (#REF! >= 'Output Tables'!$E$1) * (#REF! <= 'Output Tables'!$F$1) *#REF!)} -> #REF! | I36: =F36-H36 -> #REF!
C37: HF11 | D37: =_xlfn.XLOOKUP(C37,#REF!,#REF!,0) -> #REF! | E37: {=SUMPRODUCT((#REF! = 'Output Tables'!C37) * (#REF! >= 'Output Tables'!$E$1) * (#REF! <= 'Output Tables'!$F$1) * #REF!)} -> #REF! | F37: {=SUMPRODUCT((#REF! = 'Output Tables'!D37) * (#REF! >= 'Output Tables'!$E$1) * (#REF! <= 'Output Tables'!$F$1) *#REF!)} -> #REF! | G37: =F37-E37 -> #REF! | H37: {=SUMPRODUCT((#REF! = 'Output Tables'!$D37) * (#REF! >= 'Output Tables'!$E$1) * (#REF! <= 'Output Tables'!$F$1) *#REF!)} -> #REF! | I37: =F37-H37 -> #REF!
C38: Kiefel 2 | D38: =_xlfn.XLOOKUP(C38,#REF!,#REF!,0) -> #REF! | E38: {=SUMPRODUCT((#REF! = 'Output Tables'!C38) * (#REF! >= 'Output Tables'!$E$1) * (#REF! <= 'Output Tables'!$F$1) * #REF!)} -> #REF! | F38: {=SUMPRODUCT((#REF! = 'Output Tables'!D38) * (#REF! >= 'Output Tables'!$E$1) * (#REF! <= 'Output Tables'!$F$1) *#REF!)} -> #REF! | G38: =F38-E38 -> #REF! | H38: {=SUMPRODUCT((#REF! = 'Output Tables'!$D38) * (#REF! >= 'Output Tables'!$E$1) * (#REF! <= 'Output Tables'!$F$1) *#REF!)} -> #REF! | I38: =F38-H38 -> #REF!
C39: HU2 | D39: =_xlfn.XLOOKUP(C39,#REF!,#REF!,0) -> #REF! | E39: {=SUMPRODUCT((#REF! = 'Output Tables'!C39) * (#REF! >= 'Output Tables'!$E$1) * (#REF! <= 'Output Tables'!$F$1) * #REF!)} -> #REF! | F39: {=SUMPRODUCT((#REF! = 'Output Tables'!D39) * (#REF! >= 'Output Tables'!$E$1) * (#REF! <= 'Output Tables'!$F$1) *#REF!)} -> #REF! | G39: =F39-E39 -> #REF! | H39: {=SUMPRODUCT((#REF! = 'Output Tables'!$D39) * (#REF! >= 'Output Tables'!$E$1) * (#REF! <= 'Output Tables'!$F$1) *#REF!)} -> #REF! | I39: =F39-H39 -> #REF!
C40: HU3 | D40: =_xlfn.XLOOKUP(C40,#REF!,#REF!,0) -> #REF! | E40: {=SUMPRODUCT((#REF! = 'Output Tables'!C40) * (#REF! >= 'Output Tables'!$E$1) * (#REF! <= 'Output Tables'!$F$1) * #REF!)} -> #REF! | F40: {=SUMPRODUCT((#REF! = 'Output Tables'!D40) * (#REF! >= 'Output Tables'!$E$1) * (#REF! <= 'Output Tables'!$F$1) *#REF!)} -> #REF! | G40: =F40-E40 -> #REF! | H40: {=SUMPRODUCT((#REF! = 'Output Tables'!$D40) * (#REF! >= 'Output Tables'!$E$1) * (#REF! <= 'Output Tables'!$F$1) *#REF!)} -> #REF! | I40: =F40-H40 -> #REF!
C41: Autocoiner #3 | D41: =_xlfn.XLOOKUP(C41,#REF!,#REF!,0) -> #REF! | E41: {=SUMPRODUCT((#REF! = 'Output Tables'!C41) * (#REF! >= 'Output Tables'!$E$1) * (#REF! <= 'Output Tables'!$F$1) * #REF!)} -> #REF! | F41: {=SUMPRODUCT((#REF! = 'Output Tables'!D41) * (#REF! >= 'Output Tables'!$E$1) * (#REF! <= 'Output Tables'!$F$1) *#REF!)} -> #REF! | G41: =F41-E41 -> #REF! | H41: {=SUMPRODUCT((#REF! = 'Output Tables'!$D41) * (#REF! >= 'Output Tables'!$E$1) * (#REF! <= 'Output Tables'!$F$1) *#REF!)} -> #REF! | I41: =F41-H41 -> #REF!
C42: Autocoiner #4 | D42: =_xlfn.XLOOKUP(C42,#REF!,#REF!,0) -> #REF! | E42: {=SUMPRODUCT((#REF! = 'Output Tables'!C42) * (#REF! >= 'Output Tables'!$E$1) * (#REF! <= 'Output Tables'!$F$1) * #REF!)} -> #REF! | F42: {=SUMPRODUCT((#REF! = 'Output Tables'!D42) * (#REF! >= 'Output Tables'!$E$1) * (#REF! <= 'Output Tables'!$F$1) *#REF!)} -> #REF! | G42: =F42-E42 -> #REF! | H42: {=SUMPRODUCT((#REF! = 'Output Tables'!$D42) * (#REF! >= 'Output Tables'!$E$1) * (#REF! <= 'Output Tables'!$F$1) *#REF!)} -> #REF! | I42: =F42-H42 -> #REF!
C43: Autocoiner #5 | D43: =_xlfn.XLOOKUP(C43,#REF!,#REF!,0) -> #REF! | E43: {=SUMPRODUCT((#REF! = 'Output Tables'!C43) * (#REF! >= 'Output Tables'!$E$1) * (#REF! <= 'Output Tables'!$F$1) * #REF!)} -> #REF! | F43: {=SUMPRODUCT((#REF! = 'Output Tables'!D43) * (#REF! >= 'Output Tables'!$E$1) * (#REF! <= 'Output Tables'!$F$1) *#REF!)} -> #REF! | G43: =F43-E43 -> #REF! | H43: {=SUMPRODUCT((#REF! = 'Output Tables'!$D43) * (#REF! >= 'Output Tables'!$E$1) * (#REF! <= 'Output Tables'!$F$1) *#REF!)} -> #REF! | I43: =F43-H43 -> #REF!
...

Sheet Pouch Output
A33: Row Labels | B33: Output | C33: Target Output
A34: BA | B34: 71846564 | C34: 53937000
A35: 2024 | B35: 29326566 | C35: 28400000
A36: Qtr1 | B36: 7586666 | C36: 7640419.2
A37: Jan | B37: 2648074 | C37: 2576946.1
A38: 45292 | B38: 2648074 | C38: 2576946.1
A39: Kiefel 14 | B39: 947164 | C39: 918373.58
A40: Kiefel 3 | B40: 1008960 | C40: 754505.11
A41: Kiefel 9 | B41: 691950 | C41: 904067.41
A42: Feb | B42: 2295185 | C42: 2441317.4
A43: 45323 | B43: 2295185 | C43: 2441317.4
A44: Kiefel 14 | B44: 779755 | C44: 870038.13
A45: Kiefel 3 | B45: 745990 | C45: 714794.31
A46: Kiefel 9 | B46: 769440 | C46: 856484.92
A47: Mar | B47: 2643407 | C47: 2622155.7
A48: 45352 | B48: 2643407 | C48: 2622155.7
A49: Kiefel 14 | B49: 899697 | C49: 934485.4
A50: Kiefel 3 | B50: 936350 | C50: 767742.04
A51: Kiefel 9 | B51: 807360 | C51: 919928.25
A52: Qtr2 | B52: 7516612 | C52: 7685628.7
A53: Apr | B53: 2586573 | C53: 2531736.5
A54: 45383 | B54: 2586573 | C54: 2531736.5
A55: Kiefel 14 | B55: 889773 | C55: 902261.76
A56: Kiefel 3 | B56: 913200 | C56: 741268.18
A57: Kiefel 9 | B57: 783600 | C57: 888206.58
A58: May | B58: 2392094 | C58: 2622155.7
A59: 45413 | B59: 2392094 | C59: 2622155.7
A60: Kiefel 14 | B60: 797914 | C60: 934485.4
A61: Kiefel 3 | B61: 744540 | C61: 767742.04
A62: Kiefel 9 | B62: 849640 | C62: 919928.25
A63: Jun | B63: 2537945 | C63: 2531736.5
A64: 45444 | B64: 2537945 | C64: 2531736.5
A65: Kiefel 14 | B65: 830585 | C65: 902261.76
A66: Kiefel 3 | B66: 860280 | C66: 741268.18
A67: Kiefel 9 | B67: 847080 | C67: 888206.58
A68: Qtr3 | B68: 7090762 | C68: 6965628.7
A69: Jul | B69: 2660759 | C69: 2367574.8
A70: 45474 | B70: 2660759 | C70: 2367574.8
A71: Kiefel 14 | B71: 834679 | C71: 621709.03
A72: Kiefel 3 | B72: 904840 | C72: 794215.9
...

Sheet 12 mo trend
A3: Row Labels | B3: OEE % | C3: TEEP % | D3: Target OEE | E3: Technical OEE % | F3: Output | G3: Target Output
A4: 1Pc Autocoiner 1 (789) | B4: 0.5597213 | C4: 0.56144581 | D4: 0.71599504 | E4: 0.59485211 | F4: 3387920 | G4: 1018206.6
A5: 2025 | B5: 0.64464906 | C5: 0.65064764 | D5: 0.71599504 | E5: 0.66592931 | F5: 2016200 | G5: 1018206.6
A6: 2026 | B6: 0.47270516 | C6: 0.47126374 | D6: 0.71599504 | E6: 0.51765118 | F6: 1371720
A7: 46023 | B7: 0.45016211 | C7: 0.40962366 | D7: 0.71599504 | E7: 0.59562429 | F7: 220320
A8: 46054 | B8: 0.67069922 | C8: 0.61846264 | D8: 0.71599504 | E8: 0.68629119 | F8: 319200
A9: 46082 | B9: 0.47309797 | C9: 0.47557796 | D9: 0.71599504 | E9: 0.53565256 | F9: 239280
A10: 46113 | B10: 0.26166285 | C10: 0.26709722 | D10: 0.71599504 | E10: 0.26834074 | F10: 134280
A11: 46174 | B11: 0.50124217 | C11: 0.56325 | D11: 0.71599504 | E11: 0.51208941 | F11: 251880
A12: 46143 | B12: 0.4956017 | C12: 0.49944892 | D12: 0.71599504 | E12: 0.54406306 | F12: 206760
A13: 1Pc Autocoiner 2 (844) | B13: 0.56030178 | C13: 0.59754326 | D13: 0.72165156 | E13: 0.5908003 | F13: 3467880 | G13: 1145423
A14: 2025 | B14: 0.58618498 | C14: 0.6258356 | D14: 0.72165156 | E14: 0.62273505 | F14: 1868280 | G14: 1145423
A15: 2026 | B15: 0.53343354 | C15: 0.56894002 | D15: 0.72165156 | E15: 0.55815004 | F15: 1599600
A16: 46023 | B16: 0.54443528 | C16: 0.59610215 | D16: 0.72165156 | E16: 0.57774422 | F16: 271440
A17: 46054 | B17: 0.42686847 | C17: 0.40232759 | D17: 0.72165156 | E17: 0.47440628 | F17: 185760
A18: 46082 | B18: 0.57344521 | C18: 0.63114247 | D18: 0.72165156 | E18: 0.60687422 | F18: 306480
A19: 46113 | B19: 0.57401256 | C19: 0.64501389 | D19: 0.72165156 | E19: 0.58486085 | F19: 308880
A20: 46174 | B20: 0.51284135 | C20: 0.54402778 | D20: 0.72165156 | E20: 0.52602856 | F20: 252960
A21: 46143 | B21: 0.54598163 | C21: 0.58592742 | D21: 0.72165156 | E21: 0.55619198 | F21: 274080
A22: 1pc Autocoiner 9 (34753) | B22: 0.52080955 | C22: 0.56366462 | D22: 0.72165151 | E22: 0.59126263 | F22: 4044120 | G22: 1766251.4
A23: 2025 | B23: 0.58418572 | C23: 0.62251359 | D23: 0.72165151 | E23: 0.63610488 | F23: 2225880 | G23: 1766251.4
A24: 2026 | B24: 0.45751508 | C24: 0.50416896 | D24: 0.72165151 | E24: 0.54249417 | F24: 1818240
A25: 46023 | B25: 0.44560647 | C25: 0.48860215 | D25: 0.72165151 | E25: 0.58898766 | F25: 287040
A26: 46054 | B26: 0.53863368 | C26: 0.57527299 | D26: 0.72165151 | E26: 0.57341847 | F26: 329640
A27: 46082 | B27: 0.44132467 | C27: 0.48883065 | D27: 0.72165151 | E27: 0.53591178 | F27: 303840
A28: 46113 | B28: 0.41306439 | C28: 0.45515278 | D28: 0.72165151 | E28: 0.50159966 | F28: 255120
A29: 46174 | B29: 0.47670388 | C29: 0.52845833 | D29: 0.72165151 | E29: 0.55598277 | F29: 305040
A30: 46143 | B30: 0.43682856 | C30: 0.49248656 | D30: 0.72165151 | E30: 0.50245889 | F30: 337560
A31: 1PCAC10 | B31: 0.5800626 | C31: 0.5694046 | D31: 0.65534965 | E31: 0.6902687 | F31: 4087560 | G31: 1410841.8
A32: 2025 | B32: 0.49412615 | C32: 0.42299592 | D32: 0.65534965 | E32: 0.65734501 | F32: 1541640 | G32: 1410841.8
A33: 2026 | B33: 0.64781653 | C33: 0.71742216 | D33: 0.65534965 | E33: 0.71170542 | F33: 2545920
A34: 46023 | B34: 0.57789939 | C34: 0.64931452 | D34: 0.65534965 | E34: 0.67868561 | F34: 386880
A35: 46054 | B35: 0.64101172 | C35: 0.71079023 | D35: 0.65534965 | E35: 0.69152294 | F35: 403680
A36: 46082 | B36: 0.64432323 | C36: 0.72444892 | D36: 0.65534965 | E36: 0.69264017 | F36: 438360
A37: 46113 | B37: 0.68929228 | C37: 0.752125 | D37: 0.65534965 | E37: 0.73999192 | F37: 439560
A38: 46174 | B38: 0.60227467 | C38: 0.66940278 | D38: 0.65534965 | E38: 0.69506719 | F38: 380880
A39: 46143 | B39: 0.72967637 | C39: 0.79759409 | D39: 0.65534965 | E39: 0.76443823 | F39: 496560
A40: 2Pc Autocoiner 3 (796) | B40: 0.60571915 | C40: 0.70242828 | D40: 0.72580683 | E40: 0.68360721 | F40: 3535749 | G40: 1405881.7
A41: 2025 | B41: 0.67967811 | C41: 0.71306159 | D41: 0.72580683 | E41: 0.77726682 | F41: 1787249 | G41: 1405881.7
A42: 2026 | B42: 0.53135433 | C42: 0.69167811 | D42: 0.72580683 | E42: 0.59187753 | F42: 1748500
...

Sheet Dr Pouch Output
A33: Row Labels | B33: Output | C33: Target Output
A34: BA | B34: 71846564 | C34: 53937000
A35: 2024 | B35: 29326566 | C35: 28400000
A36: Qtr1 | B36: 7586666 | C36: 7640419.2
A37: Jan | B37: 2648074 | C37: 2576946.1
A38: 45292 | B38: 2648074 | C38: 2576946.1
A39: Kiefel 14 | B39: 947164 | C39: 918373.58
A40: Kiefel 3 | B40: 1008960 | C40: 754505.11
A41: Kiefel 9 | B41: 691950 | C41: 904067.41
A42: Feb | B42: 2295185 | C42: 2441317.4
A43: 45323 | B43: 2295185 | C43: 2441317.4
A44: Kiefel 14 | B44: 779755 | C44: 870038.13
A45: Kiefel 3 | B45: 745990 | C45: 714794.31
A46: Kiefel 9 | B46: 769440 | C46: 856484.92
A47: Mar | B47: 2643407 | C47: 2622155.7
A48: 45352 | B48: 2643407 | C48: 2622155.7
A49: Kiefel 14 | B49: 899697 | C49: 934485.4
A50: Kiefel 3 | B50: 936350 | C50: 767742.04
A51: Kiefel 9 | B51: 807360 | C51: 919928.25
A52: Qtr2 | B52: 7516612 | C52: 7685628.7
A53: Apr | B53: 2586573 | C53: 2531736.5
A54: 45383 | B54: 2586573 | C54: 2531736.5
A55: Kiefel 14 | B55: 889773 | C55: 902261.76
A56: Kiefel 3 | B56: 913200 | C56: 741268.18
A57: Kiefel 9 | B57: 783600 | C57: 888206.58
A58: May | B58: 2392094 | C58: 2622155.7
A59: 45413 | B59: 2392094 | C59: 2622155.7
A60: Kiefel 14 | B60: 797914 | C60: 934485.4
A61: Kiefel 3 | B61: 744540 | C61: 767742.04
A62: Kiefel 9 | B62: 849640 | C62: 919928.25
A63: Jun | B63: 2537945 | C63: 2531736.5
A64: 45444 | B64: 2537945 | C64: 2531736.5
A65: Kiefel 14 | B65: 830585 | C65: 902261.76
A66: Kiefel 3 | B66: 860280 | C66: 741268.18
A67: Kiefel 9 | B67: 847080 | C67: 888206.58
A68: Qtr3 | B68: 7090762 | C68: 6965628.7
A69: Jul | B69: 2660759 | C69: 2367574.8
A70: 45474 | B70: 2660759 | C70: 2367574.8
A71: Kiefel 14 | B71: 834679 | C71: 621709.03
A72: Kiefel 3 | B72: 904840 | C72: 794215.9
...

Sheet Cl Pouch Output
A33: Row Labels | B33: Output | C33: Target Output
A34: BA | B34: 5856272 | C34: 5146442.2
A35: 2024 | B35: 3987310 | C35: 3903162.9
A36: Qtr1 | B36: 1448791 | C36: 1890343.6
A37: Jan | B37: 580646 | C37: 660851.83
A38: 45292 | B38: 580646 | C38: 660851.83
A39: Kiefel 2 | B39: 580646 | C39: 660851.83
A40: Feb | B40: 502560 | C40: 614745.89
A41: 45323 | B41: 502560 | C41: 614745.89
A42: Kiefel 2 | B42: 502560 | C42: 614745.89
A43: Mar | B43: 365585 | C43: 614745.89
A44: 45352 | B44: 365585 | C44: 614745.89
A45: Kiefel 2 | B45: 365585 | C45: 614745.89
A46: Qtr2 | B46: 1602131 | C46: 1432985
A47: Apr | B47: 202091 | C47: 645483.19
A48: 45383 | B48: 202091 | C48: 645483.19
A49: Kiefel 2 | B49: 202091 | C49: 645483.19
A50: May | B50: 734400 | C50: 676220.48
A51: 45413 | B51: 734400 | C51: 676220.48
A52: Kiefel 2 | B52: 734400 | C52: 676220.48
A53: Jun | B53: 665640 | C53: 111281.32
A54: 45444 | B54: 665640 | C54: 111281.32
A55: Kiefel 2 | B55: 665640 | C55: 111281.32
A56: Qtr3 | B56: 702933 | C56: 327987.06
A57: Jul | B57: 495000 | C57: 117138.24
A58: 45474 | B58: 495000 | C58: 117138.24
A59: Kiefel 2 | B59: 495000 | C59: 117138.24
A60: Aug | B60: 103320 | C60: 87853.676
A61: 45505 | B61: 103320 | C61: 87853.676
A62: Kiefel 2 | B62: 103320 | C62: 87853.676
A63: Sep | B63: 104613 | C63: 122995.15
A64: 45536 | B64: 104613 | C64: 122995.15
A65: Kiefel 2 | B65: 104613 | C65: 122995.15
A66: Qtr4 | B66: 233455 | C66: 251847.21
A67: Oct | B67: 178180 | C67: 128852.06
A68: 45566 | B68: 178180 | C68: 128852.06
A69: Kiefel 2 | B69: 178180 | C69: 128852.06
A70: Nov | B70: 55275 | C70: 122995.15
A71: 45597 | B71: 55275 | C71: 122995.15
A72: Kiefel 2 | B72: 55275 | C72: 122995.15
...

Sheet Dansac Pouch Output
A33: Row Labels | B33: Output | C33: Target Output
A34: BA | B34: 92065054 | C34: 71862011
A35: 2024 | B35: 32531933 | C35: 33503106
A36: Qtr1 | B36: 8530240 | C36: 8219345.6
A37: Jan | B37: 2256304 | C37: 2365184.2
A38: 45292 | B38: 2256304 | C38: 2365184.2
A39: HF11 | B39: 759000 | C39: 849563.58
A40: Kiefel 10 | B40: 643380 | C40: 660633.59
A41: Kiefel 13 | B41: 853924 | C41: 854987.04
A42: Feb | B42: 3064056 | C42: 2844091.8
A43: 45323 | B43: 3064056 | C43: 2844091.8
A44: HF11 | B44: 759360 | C44: 804849.71
A45: Kiefel 10 | B45: 663501 | C45: 625863.4
A46: Kiefel 13 | B46: 919700 | C46: 809987.72
A47: P16 | B47: 721495 | C47: 603390.96
A48: Mar | B48: 3209880 | C48: 3010069.6
A49: 45352 | B49: 3209880 | C49: 3010069.6
A50: HF11 | B50: 829500 | C50: 864468.21
A51: Kiefel 10 | B51: 714400 | C51: 672223.66
A52: Kiefel 13 | B52: 972050 | C52: 869986.81
A53: P16 | B53: 693930 | C53: 603390.96
A54: Qtr2 | B54: 7702892 | C54: 8924570.2
A55: Apr | B55: 2914680 | C55: 2957250.3
A56: 45383 | B56: 2914680 | C56: 2957250.3
A57: HF11 | B57: 735600 | C57: 834658.96
A58: Kiefel 10 | B58: 544300 | C58: 649043.53
A59: Kiefel 13 | B59: 842600 | C59: 839987.27
A60: P16 | B60: 792180 | C60: 633560.51
A61: May | B61: 2245970 | C61: 3070408.7
A62: 45413 | B62: 2245970 | C62: 3070408.7
A63: HF11 | B63: 482730 | C63: 864468.21
A64: Kiefel 10 | B64: 742300 | C64: 672223.66
A65: Kiefel 13 | B65: 830300 | C65: 869986.81
A66: P16 | B66: 190640 | C66: 663730.06
A67: Jun | B67: 2542242 | C67: 2896911.2
A68: 45444 | B68: 2542242 | C68: 2896911.2
A69: HF11 | B69: 638402 | C69: 834658.96
A70: Kiefel 10 | B70: 692800 | C70: 649043.53
A71: Kiefel 13 | B71: 781240 | C71: 839987.27
A72: P16 | B72: 429800 | C72: 573221.41
...

Sheet Untagged Pouch 12 mo Trend
B3: Column Labels
B4: Untagged Target | E4: Untagged vs Loss | H4: Total Untagged Target | I4: Total Untagged vs Loss
A5: Row Labels | B5: BA | C5: KA | D5: SD | E5: BA | F5: KA | G5: SD
A6: 2024 | B6: 0.05 | C6: 0.05 | D6: 0.05 | E6: 0.15034946 | F6: 0.009319038 | G6: 0.033216408 | H6: 0.05 | I6: 0.087115286
A7: Qtr1 | B7: 0.05 | C7: 0.05 | D7: 0.05 | E7: 0.066266745 | F7: 0.014097452 | G7: 0.016515662 | H7: 0.05 | I7: 0.042407114
A8: Jan | B8: 0.05 | C8: 0.05 | D8: 0.05 | E8: 0.037175404 | F8: 0.021990279 | G8: 0.017762453 | H8: 0.05 | I8: 0.028638499
A9: 45292 | B9: 0.05 | C9: 0.05 | D9: 0.05 | E9: 0.037175404 | F9: 0.021990279 | G9: 0.017762453 | H9: 0.05 | I9: 0.028638499
A10: Feb | B10: 0.05 | C10: 0.05 | D10: 0.05 | E10: 0.036330509 | F10: 0.011697033 | G10: 0.015948307 | H10: 0.05 | I10: 0.026334948
A11: 45323 | B11: 0.05 | C11: 0.05 | D11: 0.05 | E11: 0.036330509 | F11: 0.011697033 | G11: 0.015948307 | H11: 0.05 | I11: 0.026334948
A12: Mar | B12: 0.05 | C12: 0.05 | D12: 0.05 | E12: 0.12211349 | F12: 0.0099885523 | G12: 0.015819353 | H12: 0.05 | I12: 0.070310379
A13: 45352 | B13: 0.05 | C13: 0.05 | D13: 0.05 | E13: 0.12211349 | F13: 0.0099885523 | G13: 0.015819353 | H13: 0.05 | I13: 0.070310379
A14: Qtr2 | B14: 0.05 | C14: 0.05 | D14: 0.05 | E14: 0.13773084 | F14: 0.010600215 | G14: 0.022322423 | H14: 0.05 | I14: 0.077395181
A15: Apr | B15: 0.05 | C15: 0.05 | D15: 0.05 | E15: 0.10593583 | F15: 0.013503226 | G15: 0.013005967 | H15: 0.05 | I15: 0.061983219
A16: 45383 | B16: 0.05 | C16: 0.05 | D16: 0.05 | E16: 0.10593583 | F16: 0.013503226 | G16: 0.013005967 | H16: 0.05 | I16: 0.061983219
A17: May | B17: 0.05 | C17: 0.05 | D17: 0.05 | E17: 0.15329064 | F17: 0.0089380614 | G17: 0.02039785 | H17: 0.05 | I17: 0.082195134
A18: 45413 | B18: 0.05 | C18: 0.05 | D18: 0.05 | E18: 0.15329064 | F18: 0.0089380614 | G18: 0.02039785 | H18: 0.05 | I18: 0.082195134
A19: Jun | B19: 0.05 | C19: 0.05 | D19: 0.05 | E19: 0.15238124 | F19: 0.0098285631 | G19: 0.032331883 | H19: 0.05 | I19: 0.086860704
A20: 45444 | B20: 0.05 | C20: 0.05 | D20: 0.05 | E20: 0.15238124 | F20: 0.0098285631 | G20: 0.032331883 | H20: 0.05 | I20: 0.086860704
A21: Qtr3 | B21: 0.05 | C21: 0.05 | D21: 0.05 | E21: 0.25237168 | F21: 0.0078846444 | G21: 0.015522041 | H21: 0.05 | I21: 0.13732147
A22: Jul | B22: 0.05 | C22: 0.05 | D22: 0.05 | E22: 0.21317307 | F22: 0.0045454763 | G22: 0.020887218 | H22: 0.05 | I22: 0.1028483
A23: 45474 | B23: 0.05 | C23: 0.05 | D23: 0.05 | E23: 0.21317307 | F23: 0.0045454763 | G23: 0.020887218 | H23: 0.05 | I23: 0.1028483
A24: Aug | B24: 0.05 | C24: 0.05 | D24: 0.05 | E24: 0.31436906 | F24: 0.010685553 | G24: 0.010212881 | H24: 0.05 | I24: 0.19056666
A25: 45505 | B25: 0.05 | C25: 0.05 | D25: 0.05 | E25: 0.31436906 | F25: 0.010685553 | G25: 0.010212881 | H25: 0.05 | I25: 0.19056666
A26: Sep | B26: 0.05 | C26: 0.05 | D26: 0.05 | E26: 0.19776159 | F26: 0.010710694 | G26: 0.016483147 | H26: 0.05 | I26: 0.10753847
A27: 45536 | B27: 0.05 | C27: 0.05 | D27: 0.05 | E27: 0.19776159 | F27: 0.010710694 | G27: 0.016483147 | H27: 0.05 | I27: 0.10753847
A28: Qtr4 | B28: 0.05 | C28: 0.05 | D28: 0.05 | E28: 0.12754522 | F28: 0.0059061286 | G28: 0.070147817 | H28: 0.05 | I28: 0.082120732
A29: Oct | B29: 0.05 | C29: 0.05 | D29: 0.05 | E29: 0.16209318 | F29: 0.010168765 | G29: 0.025290995 | H29: 0.05 | I29: 0.096374018
A30: 45566 | B30: 0.05 | C30: 0.05 | D30: 0.05 | E30: 0.16209318 | F30: 0.010168765 | G30: 0.025290995 | H30: 0.05 | I30: 0.096374018
A31: Nov | B31: 0.05 | C31: 0.05 | D31: 0.05 | E31: 0.097472477 | F31: 0.0066377286 | G31: 0.020929049 | H31: 0.05 | I31: 0.056313437
A32: 45597 | B32: 0.05 | C32: 0.05 | D32: 0.05 | E32: 0.097472477 | F32: 0.0066377286 | G32: 0.020929049 | H32: 0.05 | I32: 0.056313437
A33: Dec | B33: 0.05 | C33: 0.05 | D33: 0.05 | E33: 0.12183683 | F33: 0.0029434706 | G33: 0.13964706 | H33: 0.05 | I33: 0.091178277
A34: 45627 | B34: 0.05 | C34: 0.05 | D34: 0.05 | E34: 0.12183683 | F34: 0.0029434706 | G34: 0.13964706 | H34: 0.05 | I34: 0.091178277
A35: 2025 | B35: 0.05 | C35: 0.05 | D35: 0.05 | E35: 0.30804137 | F35: 0.034682051 | G35: 0.065273091 | H35: 0.05 | I35: 0.20146865
A36: Qtr1 | B36: 0.05 | C36: 0.05 | D36: 0.05 | E36: 0.21224951 | F36: 0.064029234 | G36: 0.023330514 | H36: 0.05 | I36: 0.13607228
A37: Jan | B37: 0.05 | C37: 0.05 | D37: 0.05 | E37: 0.30399964 | F37: 0.10554938 | G37: 0.019721065 | H37: 0.05 | I37: 0.19048029
A38: 45658 | B38: 0.05 | C38: 0.05 | D38: 0.05 | E38: 0.30399964 | F38: 0.10554938 | G38: 0.019721065 | H38: 0.05 | I38: 0.19048029
A39: Feb | B39: 0.05 | C39: 0.05 | D39: 0.05 | E39: 0.15882995 | F39: 0.016017858 | G39: 0.019009266 | H39: 0.05 | I39: 0.097727191
A40: 45689 | B40: 0.05 | C40: 0.05 | D40: 0.05 | E40: 0.15882995 | F40: 0.016017858 | G40: 0.019009266 | H40: 0.05 | I40: 0.097727191
A41: Mar | B41: 0.05 | C41: 0.05 | D41: 0.05 | E41: 0.16132599 | F41: 0.067852637 | G41: 0.035094142 | H41: 0.05 | I41: 0.11316115
A42: 45717 | B42: 0.05 | C42: 0.05 | D42: 0.05 | E42: 0.16132599 | F42: 0.067852637 | G42: 0.035094142 | H42: 0.05 | I42: 0.11316115
...

Sheet Untagged 1AC 12 mo Trend
B3: Column Labels
B4: Untagged Target | E4: Untagged vs Loss | H4: Total Untagged Target | I4: Total Untagged vs Loss
A5: Row Labels | B5: BA | C5: KA | D5: SD | E5: BA | F5: KA | G5: SD
A6: 2024 | B6: 0.05 | C6: 0.05 | D6: 0.05 | E6: 0.25433328 | F6: 0.0037493726 | G6: 0.0082597658 | H6: 0.05 | I6: 0.13457609
A7: Qtr1 | B7: 0.05 | C7: 0.05 | D7: 0.05 | E7: 0.12750104 | F7: #DIV/0! | G7: 0.014303706 | H7: 0.05 | I7: 0.073637511
A8: Jan | B8: 0.05 | C8: 0.05 | D8: 0.05 | E8: 0.11215177 | F8: #DIV/0! | G8: 0.0057779956 | H8: 0.05 | I8: 0.062321673
A9: 45292 | B9: 0.05 | C9: 0.05 | D9: 0.05 | E9: 0.11215177 | F9: #DIV/0! | G9: 0.0057779956 | H9: 0.05 | I9: 0.062321673
A10: Feb | B10: 0.05 | C10: 0.05 | D10: 0.05 | E10: 0.12630869 | F10: #DIV/0! | G10: 0.03033955 | H10: 0.05 | I10: 0.080820573
A11: 45323 | B11: 0.05 | C11: 0.05 | D11: 0.05 | E11: 0.12630869 | F11: #DIV/0! | G11: 0.03033955 | H11: 0.05 | I11: 0.080820573
A12: Mar | B12: 0.05 | C12: 0.05 | D12: 0.05 | E12: 0.14490081 | F12: #DIV/0! | G12: 0.008575601 | H12: 0.05 | I12: 0.07876702
A13: 45352 | B13: 0.05 | C13: 0.05 | D13: 0.05 | E13: 0.14490081 | F13: #DIV/0! | G13: 0.008575601 | H13: 0.05 | I13: 0.07876702
A14: Qtr2 | B14: 0.05 | C14: 0.05 | D14: 0.05 | E14: 0.18939025 | F14: #DIV/0! | G14: 0.0068067755 | H14: 0.05 | I14: 0.10044366
A15: Apr | B15: 0.05 | C15: 0.05 | D15: 0.05 | E15: 0.14769004 | F15: #DIV/0! | G15: 0.0061927411 | H15: 0.05 | I15: 0.076251565
A16: 45383 | B16: 0.05 | C16: 0.05 | D16: 0.05 | E16: 0.14769004 | F16: #DIV/0! | G16: 0.0061927411 | H16: 0.05 | I16: 0.076251565
A17: May | B17: 0.05 | C17: 0.05 | D17: 0.05 | E17: 0.2143907 | F17: #DIV/0! | G17: 0.0068257389 | H17: 0.05 | I17: 0.11104206
A18: 45413 | B18: 0.05 | C18: 0.05 | D18: 0.05 | E18: 0.2143907 | F18: #DIV/0! | G18: 0.0068257389 | H18: 0.05 | I18: 0.11104206
A19: Jun | B19: 0.05 | C19: 0.05 | D19: 0.05 | E19: 0.20275886 | F19: #DIV/0! | G19: 0.0075159284 | H19: 0.05 | I19: 0.11387715
A20: 45444 | B20: 0.05 | C20: 0.05 | D20: 0.05 | E20: 0.20275886 | F20: #DIV/0! | G20: 0.0075159284 | H20: 0.05 | I20: 0.11387715
A21: Qtr3 | B21: 0.05 | C21: 0.05 | D21: 0.05 | E21: 0.47780115 | F21: #DIV/0! | G21: 0.0067834251 | H21: 0.05 | I21: 0.28092729
A22: Jul | B22: 0.05 | C22: 0.05 | D22: 0.05 | E22: 0.39845646 | F22: #DIV/0! | G22: 0.0082289155 | H22: 0.05 | I22: 0.22211424
A23: 45474 | B23: 0.05 | C23: 0.05 | D23: 0.05 | E23: 0.39845646 | F23: #DIV/0! | G23: 0.0082289155 | H23: 0.05 | I23: 0.22211424
A24: Aug | B24: 0.05 | C24: 0.05 | D24: 0.05 | E24: 0.58167189 | F24: #DIV/0! | G24: 0.0060492753 | H24: 0.05 | I24: 0.40543457
A25: 45505 | B25: 0.05 | C25: 0.05 | D25: 0.05 | E25: 0.58167189 | F25: #DIV/0! | G25: 0.0060492753 | H25: 0.05 | I25: 0.40543457
A26: Sep | B26: 0.05 | C26: 0.05 | D26: 0.05 | E26: 0.29464969 | F26: #DIV/0! | G26: 0.0061870374 | H26: 0.05 | I26: 0.12840149
A27: 45536 | B27: 0.05 | C27: 0.05 | D27: 0.05 | E27: 0.29464969 | F27: #DIV/0! | G27: 0.0061870374 | H27: 0.05 | I27: 0.12840149
A28: Qtr4 | B28: 0.05 | C28: 0.05 | D28: 0.05 | E28: 0.17155938 | F28: 0.0037493726 | G28: 0.0056989925 | H28: 0.05 | I28: 0.080139813
A29: Oct | B29: 0.05 | C29: 0.05 | D29: 0.05 | E29: 0.35042899 | F29: #DIV/0! | G29: 0.0052328789 | H29: 0.05 | I29: 0.14218749
A30: 45566 | B30: 0.05 | C30: 0.05 | D30: 0.05 | E30: 0.35042899 | F30: #DIV/0! | G30: 0.0052328789 | H30: 0.05 | I30: 0.14218749
A31: Nov | B31: 0.05 | C31: 0.05 | D31: 0.05 | E31: 0.19340264 | F31: 0.0004477105 | G31: 0.0051525247 | H31: 0.05 | I31: 0.071039767
A32: 45597 | B32: 0.05 | C32: 0.05 | D32: 0.05 | E32: 0.19340264 | F32: 0.0004477105 | G32: 0.0051525247 | H32: 0.05 | I32: 0.071039767
A33: Dec | B33: 0.05 | C33: 0.05 | D33: 0.05 | E33: 0.080262469 | F33: 0.0095540537 | G33: 0.0067244767 | H33: 0.05 | I33: 0.047949853
A34: 45627 | B34: 0.05 | C34: 0.05 | D34: 0.05 | E34: 0.080262469 | F34: 0.0095540537 | G34: 0.0067244767 | H34: 0.05 | I34: 0.047949853
A35: 2025 | B35: 0.05 | C35: 0.05 | D35: 0.05 | E35: 0.069826593 | F35: 0.014427734 | G35: 0.026519877 | H35: 0.05 | I35: 0.045660066
A36: Qtr1 | B36: 0.05 | C36: 0.05 | D36: 0.05 | E36: 0.18280017 | F36: 0.034861001 | G36: 0.023134619 | H36: 0.05 | I36: 0.088817405
A37: Jan | B37: 0.05 | C37: 0.05 | D37: 0.05 | E37: 0.2474106 | F37: 0.0048122855 | G37: 0.0096687061 | H37: 0.05 | I37: 0.10210576
A38: 45658 | B38: 0.05 | C38: 0.05 | D38: 0.05 | E38: 0.2474106 | F38: 0.0048122855 | G38: 0.0096687061 | H38: 0.05 | I38: 0.10210576
A39: Feb | B39: 0.05 | C39: 0.05 | D39: 0.05 | E39: 0.16655371 | F39: 0.0072127552 | G39: 0.044600518 | H39: 0.05 | I39: 0.089517727
A40: 45689 | B40: 0.05 | C40: 0.05 | D40: 0.05 | E40: 0.16655371 | F40: 0.0072127552 | G40: 0.044600518 | H40: 0.05 | I40: 0.089517727
A41: Mar | B41: 0.05 | C41: 0.05 | D41: 0.05 | E41: 0.1140961 | F41: 0.10251799 | G41: 0.017684057 | H41: 0.05 | I41: 0.069351276
A42: 45717 | B42: 0.05 | C42: 0.05 | D42: 0.05 | E42: 0.1140961 | F42: 0.10251799 | G42: 0.017684057 | H42: 0.05 | I42: 0.069351276
...

Sheet Untagged 2AC 12 mo Trend
B3: Column Labels
B4: Untagged Target | D4: Untagged vs Loss | F4: Total Untagged Target | G4: Total Untagged vs Loss
A5: Row Labels | B5: KA | C5: SD | D5: KA | E5: SD
A6: 2024 | B6: 0.05 | C6: 0.05 | D6: 0.0049916273 | E6: 0.10210765 | F6: 0.05 | G6: 0.047069256
A7: Qtr1 | B7: 0.05 | C7: 0.05 | D7: 0.0041303622 | E7: 0.13747376 | F7: 0.05 | G7: 0.054283527
A8: Jan | B8: 0.05 | C8: 0.05 | D8: 0.0050188626 | E8: 0.13518708 | F8: 0.05 | G8: 0.053639927
A9: 45292 | B9: 0.05 | C9: 0.05 | D9: 0.0050188626 | E9: 0.13518708 | F9: 0.05 | G9: 0.053639927
A10: Feb | B10: 0.05 | C10: 0.05 | D10: 0.001851268 | E10: 0.13611914 | F10: 0.05 | G10: 0.050330319
A11: 45323 | B11: 0.05 | C11: 0.05 | D11: 0.001851268 | E11: 0.13611914 | F11: 0.05 | G11: 0.050330319
A12: Mar | B12: 0.05 | C12: 0.05 | D12: 0.0059802693 | E12: 0.14158177 | F12: 0.05 | G12: 0.059915285
A13: 45352 | B13: 0.05 | C13: 0.05 | D13: 0.0059802693 | E13: 0.14158177 | F13: 0.05 | G13: 0.059915285
A14: Qtr2 | B14: 0.05 | C14: 0.05 | D14: 0.003654021 | E14: 0.16579456 | F14: 0.05 | G14: 0.068153694
A15: Apr | B15: 0.05 | C15: 0.05 | D15: 0.0012156817 | E15: 0.16439341 | F15: 0.05 | G15: 0.057283819
A16: 45383 | B16: 0.05 | C16: 0.05 | D16: 0.0012156817 | E16: 0.16439341 | F16: 0.05 | G16: 0.057283819
A17: May | B17: 0.05 | C17: 0.05 | D17: 0.0035729117 | E17: 0.05269447 | F17: 0.05 | G17: 0.023299956
A18: 45413 | B18: 0.05 | C18: 0.05 | D18: 0.0035729117 | E18: 0.05269447 | F18: 0.05 | G18: 0.023299956
A19: Jun | B19: 0.05 | C19: 0.05 | D19: 0.0073994213 | E19: 0.28176252 | F19: 0.05 | G19: 0.13360006
A20: 45444 | B20: 0.05 | C20: 0.05 | D20: 0.0073994213 | E20: 0.28176252 | F20: 0.05 | G20: 0.13360006
A21: Qtr3 | B21: 0.05 | C21: 0.05 | D21: 0.0053976761 | E21: 0.064547398 | F21: 0.05 | G21: 0.032474793
A22: Jul | B22: 0.05 | C22: 0.05 | D22: 0.0019142326 | E22: 0.10303858 | F22: 0.05 | G22: 0.040025609
A23: 45474 | B23: 0.05 | C23: 0.05 | D23: 0.0019142326 | E23: 0.10303858 | F23: 0.05 | G23: 0.040025609
A24: Aug | B24: 0.05 | C24: 0.05 | D24: 0.0068343138 | E24: 0.044788102 | F24: 0.05 | G24: 0.026589691
A25: 45505 | B25: 0.05 | C25: 0.05 | D25: 0.0068343138 | E25: 0.044788102 | F25: 0.05 | G25: 0.026589691
A26: Sep | B26: 0.05 | C26: 0.05 | D26: 0.010460346 | E26: 0.043548527 | F26: 0.05 | G26: 0.027412256
A27: 45536 | B27: 0.05 | C27: 0.05 | D27: 0.010460346 | E27: 0.043548527 | F27: 0.05 | G27: 0.027412256
A28: Qtr4 | B28: 0.05 | C28: 0.05 | D28: 0.0074332002 | E28: 0.054791265 | F28: 0.05 | G28: 0.031216971
A29: Oct | B29: 0.05 | C29: 0.05 | D29: 0.0080240181 | E29: 0.065607663 | F29: 0.05 | G29: 0.035928977
A30: 45566 | B30: 0.05 | C30: 0.05 | D30: 0.0080240181 | E30: 0.065607663 | F30: 0.05 | G30: 0.035928977
A31: Nov | B31: 0.05 | C31: 0.05 | D31: 0.0133351 | E31: 0.051804266 | F31: 0.05 | G31: 0.036593833
A32: 45597 | B32: 0.05 | C32: 0.05 | D32: 0.0133351 | E32: 0.051804266 | F32: 0.05 | G32: 0.036593833
A33: Dec | B33: 0.05 | C33: 0.05 | D33: 0.0043843055 | E33: 0.048788622 | F33: 0.05 | G33: 0.024431631
A34: 45627 | B34: 0.05 | C34: 0.05 | D34: 0.0043843055 | E34: 0.048788622 | F34: 0.05 | G34: 0.024431631
A35: 2025 | B35: 0.05 | C35: 0.05 | D35: 0.02938041 | E35: 0.17256231 | F35: 0.05 | G35: 0.10724744
A36: Qtr1 | B36: 0.05 | C36: 0.05 | D36: 0.012779211 | E36: 0.15366007 | F36: 0.05 | G36: 0.086678806
A37: Jan | B37: 0.05 | C37: 0.05 | D37: 0.0084719953 | E37: 0.12960826 | F37: 0.05 | G37: 0.062002328
A38: 45658 | B38: 0.05 | C38: 0.05 | D38: 0.0084719953 | E38: 0.12960826 | F38: 0.05 | G38: 0.062002328
A39: Feb | B39: 0.05 | C39: 0.05 | D39: 0.017414334 | E39: 0.16191278 | F39: 0.05 | G39: 0.10527177
A40: 45689 | B40: 0.05 | C40: 0.05 | D40: 0.017414334 | E40: 0.16191278 | F40: 0.05 | G40: 0.10527177
A41: Mar | B41: 0.05 | C41: 0.05 | D41: 0.015798805 | E41: 0.1694074 | F41: 0.05 | G41: 0.10061343
A42: 45717 | B42: 0.05 | C42: 0.05 | D42: 0.015798805 | E42: 0.1694074 | F42: 0.05 | G42: 0.10061343
...

Sheet Untagged BIM 12 mo Trend
B3: Column Labels
B4: Untagged Target | E4: Untagged vs Loss | H4: Total Untagged Target | I4: Total Untagged vs Loss
A5: Row Labels | B5: BA | C5: KA | D5: SD | E5: BA | F5: KA | G5: SD
A6: 2024 | B6: 0.05 | C6: 0.05 | D6: 0.05 | E6: 0.29104245 | F6: 0.010086261 | G6: 0.044519672 | H6: 0.05 | I6: 0.081903112
A7: Qtr1 | B7: 0.05 | C7: 0.05 | D7: 0.05 | E7: 0.12599979 | F7: 0.0072775295 | G7: 0.089450517 | H7: 0.05 | I7: 0.068705311
A8: Jan | B8: 0.05 | C8: 0.05 | D8: 0.05 | E8: 0.096714432 | F8: 0.0074610675 | G8: 0.073912007 | H8: 0.05 | I8: 0.053070173
A9: 45292 | B9: 0.05 | C9: 0.05 | D9: 0.05 | E9: 0.096714432 | F9: 0.0074610675 | G9: 0.073912007 | H9: 0.05 | I9: 0.053070173
A10: Feb | B10: 0.05 | C10: 0.05 | D10: 0.05 | E10: 0.10321043 | F10: 0.0077197189 | G10: 0.11954753 | H10: 0.05 | I10: 0.078347617
A11: 45323 | B11: 0.05 | C11: 0.05 | D11: 0.05 | E11: 0.10321043 | F11: 0.0077197189 | G11: 0.11954753 | H11: 0.05 | I11: 0.078347617
A12: Mar | B12: 0.05 | C12: 0.05 | D12: 0.05 | E12: 0.1627784 | F12: 0.0065884965 | G12: 0.07592186 | H12: 0.05 | I12: 0.074746276
A13: 45352 | B13: 0.05 | C13: 0.05 | D13: 0.05 | E13: 0.1627784 | F13: 0.0065884965 | G13: 0.07592186 | H13: 0.05 | I13: 0.074746276
A14: Qtr2 | B14: 0.05 | C14: 0.05 | D14: 0.05 | E14: 0.1233953 | F14: 0.0052020568 | G14: 0.064791011 | H14: 0.05 | I14: 0.054374417
A15: Apr | B15: 0.05 | C15: 0.05 | D15: 0.05 | E15: 0.078698539 | F15: 0.0051474081 | G15: 0.05988587 | H15: 0.05 | I15: 0.042926123
A16: 45383 | B16: 0.05 | C16: 0.05 | D16: 0.05 | E16: 0.078698539 | F16: 0.0051474081 | G16: 0.05988587 | H16: 0.05 | I16: 0.042926123
A17: May | B17: 0.05 | C17: 0.05 | D17: 0.05 | E17: 0.16367982 | F17: 0.0024244535 | G17: 0.02937915 | H17: 0.05 | I17: 0.04632623
A18: 45413 | B18: 0.05 | C18: 0.05 | D18: 0.05 | E18: 0.16367982 | F18: 0.0024244535 | G18: 0.02937915 | H18: 0.05 | I18: 0.04632623
A19: Jun | B19: 0.05 | C19: 0.05 | D19: 0.05 | E19: 0.11882865 | F19: 0.0091298943 | G19: 0.10404281 | H19: 0.05 | I19: 0.07519311
A20: 45444 | B20: 0.05 | C20: 0.05 | D20: 0.05 | E20: 0.11882865 | F20: 0.0091298943 | G20: 0.10404281 | H20: 0.05 | I20: 0.07519311
A21: Qtr3 | B21: 0.05 | C21: 0.05 | D21: 0.05 | E21: 0.36518364 | F21: 0.012371931 | G21: 0.017398877 | H21: 0.05 | I21: 0.085738381
A22: Jul | B22: 0.05 | C22: 0.05 | D22: 0.05 | E22: 0.1031732 | F22: 0.0033872789 | G22: 0.02545857 | H22: 0.05 | I22: 0.030848503
A23: 45474 | B23: 0.05 | C23: 0.05 | D23: 0.05 | E23: 0.1031732 | F23: 0.0033872789 | G23: 0.02545857 | H23: 0.05 | I23: 0.030848503
A24: Aug | B24: 0.05 | C24: 0.05 | D24: 0.05 | E24: 0.60852347 | F24: 0.030323796 | G24: 0.0090481047 | H24: 0.05 | I24: 0.1527068
A25: 45505 | B25: 0.05 | C25: 0.05 | D25: 0.05 | E25: 0.60852347 | F25: 0.030323796 | G25: 0.0090481047 | H25: 0.05 | I25: 0.1527068
A26: Sep | B26: 0.05 | C26: 0.05 | D26: 0.05 | E26: 0.32493252 | F26: 0.0058408358 | G26: 0.018299569 | H26: 0.05 | I26: 0.074134804
A27: 45536 | B27: 0.05 | C27: 0.05 | D27: 0.05 | E27: 0.32493252 | F27: 0.0058408358 | G27: 0.018299569 | H27: 0.05 | I27: 0.074134804
A28: Qtr4 | B28: 0.05 | C28: 0.05 | D28: 0.05 | E28: 0.4810537 | F28: 0.016214175 | G28: 0.025639339 | H28: 0.05 | I28: 0.11124848
A29: Oct | B29: 0.05 | C29: 0.05 | D29: 0.05 | E29: 0.37589367 | F29: 0.030981206 | G29: 0.019810874 | H29: 0.05 | I29: 0.087870609
A30: 45566 | B30: 0.05 | C30: 0.05 | D30: 0.05 | E30: 0.37589367 | F30: 0.030981206 | G30: 0.019810874 | H30: 0.05 | I30: 0.087870609
A31: Nov | B31: 0.05 | C31: 0.05 | D31: 0.05 | E31: 0.359672 | F31: 0.01692878 | G31: 0.017159563 | H31: 0.05 | I31: 0.082786142
A32: 45597 | B32: 0.05 | C32: 0.05 | D32: 0.05 | E32: 0.359672 | F32: 0.01692878 | G32: 0.017159563 | H32: 0.05 | I32: 0.082786142
A33: Dec | B33: 0.05 | C33: 0.05 | D33: 0.05 | E33: 0.6555922 | F33: 0.0055847753 | G33: 0.039570883 | H33: 0.05 | I33: 0.15417261
A34: 45627 | B34: 0.05 | C34: 0.05 | D34: 0.05 | E34: 0.6555922 | F34: 0.0055847753 | G34: 0.039570883 | H34: 0.05 | I34: 0.15417261
A35: 2025 | B35: 0.05 | C35: 0.05 | D35: 0.05 | E35: 0.40617209 | F35: 0.046201743 | G35: 0.11132525 | H35: 0.05 | I35: 0.15127643
A36: Qtr1 | B36: 0.05 | C36: 0.05 | D36: 0.05 | E36: 0.47483223 | F36: 0.031350307 | G36: 0.09869106 | H36: 0.05 | I36: 0.1741393
A37: Jan | B37: 0.05 | C37: 0.05 | D37: 0.05 | E37: 0.59664733 | F37: 0.019562784 | G37: 0.096894851 | H37: 0.05 | I37: 0.22217242
A38: 45658 | B38: 0.05 | C38: 0.05 | D38: 0.05 | E38: 0.59664733 | F38: 0.019562784 | G38: 0.096894851 | H38: 0.05 | I38: 0.22217242
A39: Feb | B39: 0.05 | C39: 0.05 | D39: 0.05 | E39: 0.30200989 | F39: 0.022782099 | G39: 0.12219494 | H39: 0.05 | I39: 0.14023738
A40: 45689 | B40: 0.05 | C40: 0.05 | D40: 0.05 | E40: 0.30200989 | F40: 0.022782099 | G40: 0.12219494 | H40: 0.05 | I40: 0.14023738
A41: Mar | B41: 0.05 | C41: 0.05 | D41: 0.05 | E41: 0.46113065 | F41: 0.053352369 | G41: 0.07921971 | H41: 0.05 | I41: 0.15496493
A42: 45717 | B42: 0.05 | C42: 0.05 | D42: 0.05 | E42: 0.46113065 | F42: 0.053352369 | G42: 0.07921971 | H42: 0.05 | I42: 0.15496493
...

Sheet 12 mo trend losses
A3: Row Labels | B3: OEE % | C3: Uptime % | D3: Target OEE | E3: Output | F3: Technical Loss % | G3: Non-Technical Loss %
A4: Keifel12 (979) | B4: 0.62361395 | C4: 0.6360657 | D4: 19.406 | E4: 29091284 | F4: 0.18616024 | G4: 0.03280904
A5: 2024 | B5: 0.58188757 | C5: 0.66674294 | D5: 7.512 | E5: 12122862 | F5: 0.17152706 | G5: 0.037074563
A6: Qtr1 | B6: 0.58631845 | C6: 0.68253663 | D6: 1.878 | E6: 3066410 | F6: 0.1478284 | G6: 0.051647509
A7: Jan | B7: 0.55244016 | C7: 0.66044355 | D7: 0.626 | E7: 1001585 | F7: 0.14273027 | G7: 0.072612704
A8: 45292 | B8: 0.55244016 | C8: 0.66044355 | D8: 0.626 | E8: 1001585 | F8: 0.14273027 | G8: 0.072612704
A9: Feb | B9: 0.64729951 | C9: 0.71126437 | D9: 0.626 | E9: 1009617 | F9: 0.12157825 | G9: 0.02264048
A10: 45323 | B10: 0.64729951 | C10: 0.71126437 | D10: 0.626 | E10: 1009617 | F10: 0.12157825 | G10: 0.02264048
A11: Mar | B11: 0.56639767 | C11: 0.67775538 | D11: 0.626 | E11: 1055208 | F11: 0.17630956 | G11: 0.056217742
A12: 45352 | B12: 0.56639767 | C12: 0.67775538 | D12: 0.626 | E12: 1055208 | F12: 0.17630956 | G12: 0.056217742
A13: Qtr2 | B13: 0.56126588 | C13: 0.68721154 | D13: 1.878 | E13: 3058082 | F13: 0.17974131 | G13: 0.03016895
A14: Apr | B14: 0.53888287 | C14: 0.68554167 | D14: 0.626 | E14: 971929 | F14: 0.20622468 | G14: 0.032977692
A15: 45383 | B15: 0.53888287 | C15: 0.68554167 | D15: 0.626 | E15: 971929 | F15: 0.20622468 | G15: 0.032977692
A16: May | B16: 0.56606128 | C16: 0.67260753 | D16: 0.626 | E16: 1025813 | F16: 0.17404028 | G16: 0.032162736
A17: 45413 | B17: 0.56606128 | C17: 0.67260753 | D17: 0.626 | E17: 1025813 | F17: 0.17404028 | G17: 0.032162736
A18: Jun | B18: 0.57910168 | C18: 0.70397222 | D18: 0.626 | E18: 1060340 | F18: 0.15866551 | G18: 0.025317735
A19: 45444 | B19: 0.57910168 | C19: 0.70397222 | D19: 0.626 | E19: 1060340 | F19: 0.15866551 | G19: 0.025317735
A20: Qtr3 | B20: 0.59464954 | C20: 0.69132246 | D20: 1.878 | E20: 3215193 | F20: 0.15892875 | G20: 0.033506607
A21: Jul | B21: 0.60457345 | C21: 0.68263441 | D21: 0.626 | E21: 1081539 | F21: 0.14539007 | G21: 0.045034002
A22: 45474 | B22: 0.60457345 | C22: 0.68263441 | D22: 0.626 | E22: 1081539 | F22: 0.14539007 | G22: 0.045034002
A23: Aug | B23: 0.60899042 | C23: 0.70733871 | D23: 0.626 | E23: 1111559 | F23: 0.15338344 | G23: 0.034350983
A24: 45505 | B24: 0.60899042 | C24: 0.70733871 | D24: 0.626 | E24: 1111559 | F24: 0.15338344 | G24: 0.034350983
A25: Sep | B25: 0.56989122 | C25: 0.68375 | D25: 0.626 | E25: 1022095 | F25: 0.1782226 | G25: 0.021084337
A26: 45536 | B26: 0.56989122 | C26: 0.68375 | D26: 0.626 | E26: 1022095 | F26: 0.1782226 | G26: 0.021084337
A27: Qtr4 | B27: 0.58574594 | C27: 0.60629529 | D27: 1.878 | E27: 2783177 | F27: 0.20052436 | G27: 0.033119837
A28: Oct | B28: 0.59073088 | C28: 0.68467742 | D28: 0.626 | E28: 1070855 | F28: 0.15281593 | G28: 0.040378892
A29: 45566 | B29: 0.59073088 | C29: 0.68467742 | D29: 0.626 | E29: 1070855 | F29: 0.15281593 | G29: 0.040378892
A30: Nov | B30: 0.5409232 | C30: 0.54469444 | D30: 0.626 | E30: 791171 | F30: 0.21972783 | G30: 0.03111262
A31: 45597 | B31: 0.5409232 | C31: 0.54469444 | D31: 0.626 | E31: 791171 | F31: 0.21972783 | G31: 0.03111262
A32: Dec | B32: 0.62280501 | C32: 0.58752688 | D32: 0.626 | E32: 921151 | F32: 0.23332264 | G32: 0.02726453
A33: 45627 | B33: 0.62280501 | C33: 0.58752688 | D33: 0.626 | E33: 921151 | F33: 0.23332264 | G33: 0.02726453
A34: 2025 | B34: 0.68377919 | C34: 0.67135246 | D34: 7.512 | E34: 12549117 | F34: 0.17717133 | G34: 0.033612349
A35: Qtr1 | B35: 0.63288979 | C35: 0.63441392 | D35: 1.878 | E35: 2820528 | F35: 0.2061387 | G35: 0.031104076
A36: Jan | B36: 0.63243879 | C36: 0.63170699 | D36: 0.626 | E36: 942319 | F36: 0.1946066 | G36: 0.045308007
A37: 45658 | B37: 0.63243879 | C37: 0.63170699 | D37: 0.626 | E37: 942319 | F37: 0.1946066 | G37: 0.045308007
A38: Feb | B38: 0.58399882 | C38: 0.56163793 | D38: 0.626 | E38: 806793 | F38: 0.26700268 | G38: 0.023253911
A39: 45689 | B39: 0.58399882 | C39: 0.56163793 | D39: 0.626 | E39: 806793 | F39: 0.26700268 | G39: 0.023253911
A40: Mar | B40: 0.67470564 | C40: 0.70520161 | D40: 0.626 | E40: 1071416 | F40: 0.16561851 | G40: 0.024200028
A41: 45717 | B41: 0.67470564 | C41: 0.70520161 | D41: 0.626 | E41: 1071416 | F41: 0.16561851 | G41: 0.024200028
A42: Qtr2 | B42: 0.69740653 | C42: 0.69407967 | D42: 1.878 | E42: 3243106 | F42: 0.16014669 | G42: 0.03588818
...

Sheet DT Waterfall
A58: Row Labels | B58: Avail Hours | C58: Uptime | D58: Technical Loss | E58: Non-Technical Loss | F58: Untagged | G58: Material Replenish | H58: Wait for Support | I58: Changeover | J58: Planned Loss | K58: PM & Protocol Hrs | L58: TEEP % | M58: OEE %
A59: Keifel12 (979) | B59: 4368 | C59: 2227.24 | D59: 790.92 | E59: 73.96 | F59: 177.39 | G59: 70.74 | H59: 2.47 | I59: 70.59 | J59: 138.5 | K59: 815.98 | L59: 0.50989927 | M59: 0.58939563
A60: Kiefel 14 | B60: 4368 | C60: 2632.47 | D60: 849.06 | E60: 85.94 | F60: 274.49 | G60: 220.36 | H60: 7 | I60: 76.45 | J60: 132.91 | K60: 65.44 | L60: 0.6026717 | M60: 0.53456415
A61: PCH17 | B61: 2928 | C61: 1543.09 | D61: 588.8 | E61: 239.54 | F61: 20.31 | G61: 155.99 | H61: 138.84 | I61: 28.22 | J61: 74.01 | K61: 250.02 | L61: 0.52701161 | M61: 0.45938728
A62: Grand Total | B62: 11664 | C62: 6402.8 | D62: 2228.78 | E62: 399.44 | F62: 472.19 | G62: 447.09 | H62: 148.31 | I62: 175.26 | J62: 345.42 | K62: 1131.44 | L62: 0.5489369 | M62: 0.53291603

Sheet DT Pie Chart
B3: Column Labels
A4: Values | B4: Kiefel 3
A5: Sum of Uptime | B5: 459.83
A6: Sum of Technical Loss | B6: 127.53
A7: Sum of Non-Technical Loss | B7: 16.98
A8: Sum of Untagged | B8: 81.75
A9: Sum of Material Replenish | B9: 40.28
A10: Sum of Wait for Support | B10: 1.34
A11: Sum of Changeover | B11: 6.06
A12: Sum of Planned Loss | B12: 7.9
A13: Sum of PM & Protocol Hrs | B13: 2.35

Sheet Plant Dashboard
A1: Plant | B1: SD
A3: Row Labels | B3: Average of Performance Ratio | C3: Average of Quality Loss % | D3: Average of OEE % | E3: Average of Technical Loss % | F3: Average of Non-Technical Loss % | G3: Average of Material Replenish % | H3: Average of Untagged %
